Traceback (most recent call last):
  File "/usr/local/lib/python3.6/site-packages/urllib3/connectionpool.py", line 706, in urlopen
    chunked=chunked,
  File "/usr/local/lib/python3.6/site-packages/urllib3/connectionpool.py", line 382, in _make_request
    self._validate_conn(conn)
  File "/usr/local/lib/python3.6/site-packages/urllib3/connectionpool.py", line 1010, in _validate_conn
    conn.connect()
  File "/usr/local/lib/python3.6/site-packages/urllib3/connection.py", line 421, in connect
    tls_in_tls=tls_in_tls,
  File "/usr/local/lib/python3.6/site-packages/urllib3/util/ssl_.py", line 429, in ssl_wrap_socket
    sock, context, tls_in_tls, server_hostname=server_hostname
  File "/usr/local/lib/python3.6/site-packages/urllib3/util/ssl_.py", line 472, in _ssl_wrap_socket_impl
    return ssl_context.wrap_socket(sock, server_hostname=server_hostname)
  File "/usr/local/lib/python3.6/ssl.py", line 407, in wrap_socket
    _context=self, _session=session)
  File "/usr/local/lib/python3.6/ssl.py", line 817, in __init__
    self.do_handshake()
  File "/usr/local/lib/python3.6/ssl.py", line 1077, in do_handshake
    self._sslobj.do_handshake()
  File "/usr/local/lib/python3.6/ssl.py", line 689, in do_handshake
    self._sslobj.do_handshake()
ssl.SSLError: [SSL: CERTIFICATE_VERIFY_FAILED] certificate verify failed (_ssl.c:852)

During handling of the above exception, another exception occurred:

Traceback (most recent call last):
  File "apis/api.py", line 381, in <module>
    migrate.run()
  File "/usr/src/app/apis/migrate.py", line 277, in run
    raise e
  File "/usr/src/app/apis/migrate.py", line 271, in run
    upgrade(version)
  File "/usr/src/app/apis/migrate.py", line 32, in upgrade
    create_k8s_user()
  File "/usr/src/app/apis/migrate.py", line 62, in create_k8s_user
    k8s_sa_list = kubernetesClient.list_service_account()
  File "/usr/src/app/apis/resources/kubernetesClient.py", line 108, in list_service_account
    for sa in v1.list_namespaced_service_account("account").items:
  File "/usr/local/lib/python3.6/site-packages/kubernetes/client/api/core_v1_api.py", line 16256, in list_namespaced_service_account
    return self.list_namespaced_service_account_with_http_info(namespace, **kwargs)  # noqa: E501
  File "/usr/local/lib/python3.6/site-packages/kubernetes/client/api/core_v1_api.py", line 16381, in list_namespaced_service_account_with_http_info
    collection_formats=collection_formats)
  File "/usr/local/lib/python3.6/site-packages/kubernetes/client/api_client.py", line 353, in call_api
    _preload_content, _request_timeout, _host)
  File "/usr/local/lib/python3.6/site-packages/kubernetes/client/api_client.py", line 184, in __call_api
    _request_timeout=_request_timeout)
  File "/usr/local/lib/python3.6/site-packages/kubernetes/client/api_client.py", line 377, in request
    headers=headers)
  File "/usr/local/lib/python3.6/site-packages/kubernetes/client/rest.py", line 243, in GET
    query_params=query_params)
  File "/usr/local/lib/python3.6/site-packages/kubernetes/client/rest.py", line 216, in request
    headers=headers)
  File "/usr/local/lib/python3.6/site-packages/urllib3/request.py", line 75, in request
    method, url, fields=fields, headers=headers, **urlopen_kw
  File "/usr/local/lib/python3.6/site-packages/urllib3/request.py", line 96, in request_encode_url
    return self.urlopen(method, url, **extra_kw)
  File "/usr/local/lib/python3.6/site-packages/urllib3/poolmanager.py", line 375, in urlopen
    response = conn.urlopen(method, u.request_uri, **kw)
  File "/usr/local/lib/python3.6/site-packages/urllib3/connectionpool.py", line 796, in urlopen
    **response_kw
  File "/usr/local/lib/python3.6/site-packages/urllib3/connectionpool.py", line 796, in urlopen
    **response_kw
  File "/usr/local/lib/python3.6/site-packages/urllib3/connectionpool.py", line 796, in urlopen
    **response_kw
  File "/usr/local/lib/python3.6/site-packages/urllib3/connectionpool.py", line 756, in urlopen
    method, url, error=e, _pool=self, _stacktrace=sys.exc_info()[2]
  File "/usr/local/lib/python3.6/site-packages/urllib3/util/retry.py", line 573, in increment
    raise MaxRetryError(_pool, url, error or ResponseError(cause))
urllib3.exceptions.MaxRetryError: HTTPSConnectionPool(host='rancher.10.20.0.68.xip.io', port=443): Max retries exceeded with url: /k8s/clusters/local/api/v1/namespaces/account/serviceaccounts (Caused by SSLError(SSLError(1, '[SSL: CERTIFICATE_VERIFY_FAILED] certificate verify failed (_ssl.c:852)'),))
Traceback (most recent call last):
  File "/usr/local/lib/python3.6/site-packages/urllib3/connectionpool.py", line 706, in urlopen
    chunked=chunked,
  File "/usr/local/lib/python3.6/site-packages/urllib3/connectionpool.py", line 382, in _make_request
    self._validate_conn(conn)
  File "/usr/local/lib/python3.6/site-packages/urllib3/connectionpool.py", line 1010, in _validate_conn
    conn.connect()
  File "/usr/local/lib/python3.6/site-packages/urllib3/connection.py", line 421, in connect
    tls_in_tls=tls_in_tls,
  File "/usr/local/lib/python3.6/site-packages/urllib3/util/ssl_.py", line 429, in ssl_wrap_socket
    sock, context, tls_in_tls, server_hostname=server_hostname
  File "/usr/local/lib/python3.6/site-packages/urllib3/util/ssl_.py", line 472, in _ssl_wrap_socket_impl
    return ssl_context.wrap_socket(sock, server_hostname=server_hostname)
  File "/usr/local/lib/python3.6/ssl.py", line 407, in wrap_socket
    _context=self, _session=session)
  File "/usr/local/lib/python3.6/ssl.py", line 817, in __init__
    self.do_handshake()
  File "/usr/local/lib/python3.6/ssl.py", line 1077, in do_handshake
    self._sslobj.do_handshake()
  File "/usr/local/lib/python3.6/ssl.py", line 689, in do_handshake
    self._sslobj.do_handshake()
ssl.SSLError: [SSL: CERTIFICATE_VERIFY_FAILED] certificate verify failed (_ssl.c:852)

During handling of the above exception, another exception occurred:

Traceback (most recent call last):
  File "apis/api.py", line 387, in <module>
    raise e
  File "apis/api.py", line 381, in <module>
    migrate.run()
  File "/usr/src/app/apis/migrate.py", line 277, in run
    raise e
  File "/usr/src/app/apis/migrate.py", line 271, in run
    upgrade(version)
  File "/usr/src/app/apis/migrate.py", line 32, in upgrade
    create_k8s_user()
  File "/usr/src/app/apis/migrate.py", line 62, in create_k8s_user
    k8s_sa_list = kubernetesClient.list_service_account()
  File "/usr/src/app/apis/resources/kubernetesClient.py", line 108, in list_service_account
    for sa in v1.list_namespaced_service_account("account").items:
  File "/usr/local/lib/python3.6/site-packages/kubernetes/client/api/core_v1_api.py", line 16256, in list_namespaced_service_account
    return self.list_namespaced_service_account_with_http_info(namespace, **kwargs)  # noqa: E501
  File "/usr/local/lib/python3.6/site-packages/kubernetes/client/api/core_v1_api.py", line 16381, in list_namespaced_service_account_with_http_info
    collection_formats=collection_formats)
  File "/usr/local/lib/python3.6/site-packages/kubernetes/client/api_client.py", line 353, in call_api
    _preload_content, _request_timeout, _host)
  File "/usr/local/lib/python3.6/site-packages/kubernetes/client/api_client.py", line 184, in __call_api
    _request_timeout=_request_timeout)
  File "/usr/local/lib/python3.6/site-packages/kubernetes/client/api_client.py", line 377, in request
    headers=headers)
  File "/usr/local/lib/python3.6/site-packages/kubernetes/client/rest.py", line 243, in GET
    query_params=query_params)
  File "/usr/local/lib/python3.6/site-packages/kubernetes/client/rest.py", line 216, in request
    headers=headers)
  File "/usr/local/lib/python3.6/site-packages/urllib3/request.py", line 75, in request
    method, url, fields=fields, headers=headers, **urlopen_kw
  File "/usr/local/lib/python3.6/site-packages/urllib3/request.py", line 96, in request_encode_url
    return self.urlopen(method, url, **extra_kw)
  File "/usr/local/lib/python3.6/site-packages/urllib3/poolmanager.py", line 375, in urlopen
    response = conn.urlopen(method, u.request_uri, **kw)
  File "/usr/local/lib/python3.6/site-packages/urllib3/connectionpool.py", line 796, in urlopen
    **response_kw
  File "/usr/local/lib/python3.6/site-packages/urllib3/connectionpool.py", line 796, in urlopen
    **response_kw
  File "/usr/local/lib/python3.6/site-packages/urllib3/connectionpool.py", line 796, in urlopen
    **response_kw
  File "/usr/local/lib/python3.6/site-packages/urllib3/connectionpool.py", line 756, in urlopen
    method, url, error=e, _pool=self, _stacktrace=sys.exc_info()[2]
  File "/usr/local/lib/python3.6/site-packages/urllib3/util/retry.py", line 573, in increment
    raise MaxRetryError(_pool, url, error or ResponseError(cause))
urllib3.exceptions.MaxRetryError: HTTPSConnectionPool(host='rancher.10.20.0.68.xip.io', port=443): Max retries exceeded with url: /k8s/clusters/local/api/v1/namespaces/account/serviceaccounts (Caused by SSLError(SSLError(1, '[SSL: CERTIFICATE_VERIFY_FAILED] certificate verify failed (_ssl.c:852)'),))
